<?xml version="1.0" encoding="UTF-8"?>
<testng-results ignored="0" total="2" passed="0" failed="2" skipped="0">
  <reporter-output>
  </reporter-output>
  <suite started-at="2024-06-24T01:51:15 IST" name="Realtime" finished-at="2024-06-24T01:51:28 IST" duration-ms="13534">
    <groups>
      <group name="Errorvalidation">
        <method signature="Error_Validation_Test.logininvalid_Credencial()[pri:0, instance:framework.Testcase.Error_Validation_Test@539d019]" name="logininvalid_Credencial" class="framework.Testcase.Error_Validation_Test"/>
      </group> <!-- Errorvalidation -->
    </groups>
    <test started-at="2024-06-24T01:51:15 IST" name="Errorvalidation" finished-at="2024-06-24T01:51:28 IST" duration-ms="13534">
      <class name="framework.Testcase.Error_Validation_Test">
        <test-method is-config="true" signature="launching_App()[pri:0, instance:framework.Testcase.Error_Validation_Test@539d019]" started-at="2024-06-24T01:51:15 IST" name="launching_App" finished-at="2024-06-24T01:51:19 IST" duration-ms="3958" status="PASS">
          <reporter-output>
          </reporter-output>
        </test-method> <!-- launching_App -->
        <test-method signature="logininvalid_Credencial()[pri:0, instance:framework.Testcase.Error_Validation_Test@539d019]" started-at="2024-06-24T01:51:19 IST" name="logininvalid_Credencial" finished-at="2024-06-24T01:51:20 IST" duration-ms="775" status="FAIL">
          <exception class="java.lang.AssertionError">
            <message>
              <![CDATA[expected [Incorrect email password.] but found [Incorrect email or password.]]]>
            </message>
            <full-stacktrace>
              <![CDATA[java.lang.AssertionError: expected [Incorrect email password.] but found [Incorrect email or password.]
at org.testng.Assert.fail(Assert.java:111)
at org.testng.Assert.failNotEquals(Assert.java:1578)
at org.testng.Assert.assertEqualsImpl(Assert.java:150)
at org.testng.Assert.assertEquals(Assert.java:132)
at org.testng.Assert.assertEquals(Assert.java:656)
at org.testng.Assert.assertEquals(Assert.java:666)
at framework.Testcase.Error_Validation_Test.logininvalid_Credencial(Error_Validation_Test.java:17)
at java.base/jdk.internal.reflect.NativeMethodAccessorImpl.invoke0(Native Method)
at java.base/jdk.internal.reflect.NativeMethodAccessorImpl.invoke(NativeMethodAccessorImpl.java:77)
at java.base/jdk.internal.reflect.DelegatingMethodAccessorImpl.invoke(DelegatingMethodAccessorImpl.java:43)
at java.base/java.lang.reflect.Method.invoke(Method.java:568)
at org.testng.internal.invokers.MethodInvocationHelper.invokeMethod(MethodInvocationHelper.java:139)
at org.testng.internal.invokers.TestInvoker.invokeMethod(TestInvoker.java:664)
at org.testng.internal.invokers.TestInvoker.invokeTestMethod(TestInvoker.java:228)
at org.testng.internal.invokers.MethodRunner.runInSequence(MethodRunner.java:63)
at org.testng.internal.invokers.TestInvoker$MethodInvocationAgent.invoke(TestInvoker.java:961)
at org.testng.internal.invokers.TestInvoker.invokeTestMethods(TestInvoker.java:201)
at org.testng.internal.invokers.TestMethodWorker.invokeTestMethods(TestMethodWorker.java:148)
at org.testng.internal.invokers.TestMethodWorker.run(TestMethodWorker.java:128)
at java.base/java.util.ArrayList.forEach(ArrayList.java:1511)
at org.testng.TestRunner.privateRun(TestRunner.java:819)
at org.testng.TestRunner.run(TestRunner.java:619)
at org.testng.SuiteRunner.runTest(SuiteRunner.java:443)
at org.testng.SuiteRunner.runSequentially(SuiteRunner.java:437)
at org.testng.SuiteRunner.privateRun(SuiteRunner.java:397)
at org.testng.SuiteRunner.run(SuiteRunner.java:336)
at org.testng.SuiteRunnerWorker.runSuite(SuiteRunnerWorker.java:52)
at org.testng.SuiteRunnerWorker.run(SuiteRunnerWorker.java:95)
at org.testng.TestNG.runSuitesSequentially(TestNG.java:1301)
at org.testng.TestNG.runSuitesLocally(TestNG.java:1228)
at org.testng.TestNG.runSuites(TestNG.java:1134)
at org.testng.TestNG.run(TestNG.java:1101)
at org.testng.remote.AbstractRemoteTestNG.run(AbstractRemoteTestNG.java:115)
at org.testng.remote.RemoteTestNG.initAndRun(RemoteTestNG.java:251)
at org.testng.remote.RemoteTestNG.main(RemoteTestNG.java:77)
]]>
            </full-stacktrace>
          </exception> <!-- java.lang.AssertionError -->
          <reporter-output>
          </reporter-output>
        </test-method> <!-- logininvalid_Credencial -->
        <test-method is-config="true" signature="close()[pri:0, instance:framework.Testcase.Error_Validation_Test@539d019]" started-at="2024-06-24T01:51:20 IST" name="close" finished-at="2024-06-24T01:51:20 IST" duration-ms="235" status="PASS">
          <reporter-output>
          </reporter-output>
        </test-method> <!-- close -->
        <test-method is-config="true" signature="launching_App()[pri:0, instance:framework.Testcase.Error_Validation_Test@539d019]" started-at="2024-06-24T01:51:20 IST" name="launching_App" finished-at="2024-06-24T01:51:25 IST" duration-ms="4811" status="PASS">
          <reporter-output>
          </reporter-output>
        </test-method> <!-- launching_App -->
        <test-method signature="productErrorValidation()[pri:0, instance:framework.Testcase.Error_Validation_Test@539d019]" started-at="2024-06-24T01:51:25 IST" name="productErrorValidation" finished-at="2024-06-24T01:51:28 IST" duration-ms="2901" status="FAIL">
          <exception class="java.lang.AssertionError">
            <message>
              <![CDATA[expected [true] but found [false]]]>
            </message>
            <full-stacktrace>
              <![CDATA[java.lang.AssertionError: expected [true] but found [false]
at org.testng.Assert.fail(Assert.java:111)
at org.testng.Assert.failNotEquals(Assert.java:1578)
at org.testng.Assert.assertTrue(Assert.java:57)
at org.testng.Assert.assertTrue(Assert.java:67)
at framework.Testcase.Error_Validation_Test.productErrorValidation(Error_Validation_Test.java:30)
at java.base/jdk.internal.reflect.NativeMethodAccessorImpl.invoke0(Native Method)
at java.base/jdk.internal.reflect.NativeMethodAccessorImpl.invoke(NativeMethodAccessorImpl.java:77)
at java.base/jdk.internal.reflect.DelegatingMethodAccessorImpl.invoke(DelegatingMethodAccessorImpl.java:43)
at java.base/java.lang.reflect.Method.invoke(Method.java:568)
at org.testng.internal.invokers.MethodInvocationHelper.invokeMethod(MethodInvocationHelper.java:139)
at org.testng.internal.invokers.TestInvoker.invokeMethod(TestInvoker.java:664)
at org.testng.internal.invokers.TestInvoker.invokeTestMethod(TestInvoker.java:228)
at org.testng.internal.invokers.MethodRunner.runInSequence(MethodRunner.java:63)
at org.testng.internal.invokers.TestInvoker$MethodInvocationAgent.invoke(TestInvoker.java:961)
at org.testng.internal.invokers.TestInvoker.invokeTestMethods(TestInvoker.java:201)
at org.testng.internal.invokers.TestMethodWorker.invokeTestMethods(TestMethodWorker.java:148)
at org.testng.internal.invokers.TestMethodWorker.run(TestMethodWorker.java:128)
at java.base/java.util.ArrayList.forEach(ArrayList.java:1511)
at org.testng.TestRunner.privateRun(TestRunner.java:819)
at org.testng.TestRunner.run(TestRunner.java:619)
at org.testng.SuiteRunner.runTest(SuiteRunner.java:443)
at org.testng.SuiteRunner.runSequentially(SuiteRunner.java:437)
at org.testng.SuiteRunner.privateRun(SuiteRunner.java:397)
at org.testng.SuiteRunner.run(SuiteRunner.java:336)
at org.testng.SuiteRunnerWorker.runSuite(SuiteRunnerWorker.java:52)
at org.testng.SuiteRunnerWorker.run(SuiteRunnerWorker.java:95)
at org.testng.TestNG.runSuitesSequentially(TestNG.java:1301)
at org.testng.TestNG.runSuitesLocally(TestNG.java:1228)
at org.testng.TestNG.runSuites(TestNG.java:1134)
at org.testng.TestNG.run(TestNG.java:1101)
at org.testng.remote.AbstractRemoteTestNG.run(AbstractRemoteTestNG.java:115)
at org.testng.remote.RemoteTestNG.initAndRun(RemoteTestNG.java:251)
at org.testng.remote.RemoteTestNG.main(RemoteTestNG.java:77)
]]>
            </full-stacktrace>
          </exception> <!-- java.lang.AssertionError -->
          <reporter-output>
          </reporter-output>
        </test-method> <!-- productErrorValidation -->
        <test-method is-config="true" signature="close()[pri:0, instance:framework.Testcase.Error_Validation_Test@539d019]" started-at="2024-06-24T01:51:28 IST" name="close" finished-at="2024-06-24T01:51:28 IST" duration-ms="244" status="PASS">
          <reporter-output>
          </reporter-output>
        </test-method> <!-- close -->
      </class> <!-- framework.Testcase.Error_Validation_Test -->
    </test> <!-- Errorvalidation -->
  </suite> <!-- Realtime -->
</testng-results>
